Workbook

Sheet Règles
B1: Domaines | C1: Elément | D1: Défense | E1: Type | G1: Attributs | H1: Fort contre | I1: Faible contre | J1: Ressources + | K1: Ressources - | L1: Condition + | M1: Condition - | N1: Climat | O1: Caractéristique + | P1: Caractéristique - | Q1: Compétence
A2: 🔥 | B2: Feu | C2: (énergie) chaleur, (continue) feu | D2: vs FOR | E2: Physique | F2: Intangible | G2: Force, Charisme | J2: Rage | K2: Garde | N2: Température + | O2: Puissance (x1), Dégats (x2)
A3: ❄️ | B3: Glace | C3: (énergie) froid, (continue) glace | D3: vs DEX | E3: Physique | F3: Intangible | G3: Dextérité, Intelligence | J3: Garde | K3: Rage | N3: Température - | O3: Absorption (x2), Contournement (x3)
A4: ⚡ | B4: Foudre | C4: (énergie) éléctricité, (continue) foudre | D4: vs AGI | E4: Physique | F4: Intangible | G4: Agilité, Ruse | J4: Adrénaline | K4: Adrénaline | O4: Vitesse (x1), Rapidité (x1), Perforation (x2)
A5: 🪨 | B5: Terre | C5: (physique) Terre | D5: vs CON | E5: Physique | F5: Tangible | G5: Force, Charisme | K5: Initiative | O5: Protection (x1), Déviation (x2)
A6: 💧 | B6: Eau | C6: (physique) eau | D6: vs CON | E6: Physique | F6: Tangible | G6: Dextérité, Intelligence | K6: Initiative | O6: Défense vs tactiques (x1), impact (x2)
A7: 🌪️ | B7: Air | C7: (physique) air | D7: vs CON | E7: Physique | F7: Tangible | G7: Agilité, Ruse | K7: Initiative | L7: Initiative | O7: Défense vs attaques (x1), ALure (x0.5)
A8: ☀️ | B8: Lumière | C8: (primordial) lumière | D8: vs PER | E8: Physique | F8: Intangible | O8: Adresse (x1), Visée (x0.5), Précision (x1), Criticité (x1)
A9: 🌑 | B9: Ombre | C9: (primordial) ombre | D9: vs PER | E9: Physique | F9: Intangible | O9: Maladresse (x1)
A10: ⚖️ | B10: Loi | C10: (fondamental) loi | D10: vs VOL | E10: Physique | F10: Intangible | G10: Chance
A11: 🌀 | B11: Chaos | C11: (fondamental) chaos | D11: vs VOL | E11: Physique | F11: Intangible | G11: Chance | O11: Fortune
A12: ✨ | B12: Sacre | C12: (origine) sacré | D12: vs SAG | E12: Physique | F12: Intangible | J12: Karma
A13: 🩸 | B13: Impie | C13: (origine) impie | D13: vs RUS | E13: Physique | F13: Intangible | K13: Karma
A14: ❤️ | B14: Vie | C14: (cycle) vie | D14: vs CON | E14: Physique | J14: Vitalité
A15: ☠️ | B15: Mort | C15: (cycle) mort | D15: vs CON | E15: Physique | F15: Tangible | K15: Vitalité | O15: Gravité (x2)
A16: ⚕️ | B16: Corps | G16: Les 5 Corps, Stature, Taille | J16: Vitalité | K16: Vitalité | O16: Récup Physique (x1), Robustesse, Réflexes
A17: 🧠 | B17: Esprit | G17: Les 5 Esprits, Ego, Apparence | J17: Psyché | K17: Psyché | O17: Récup Mentale (x1), Détermination, Sang Froid
A18: 🐗 | B18: Faune | G18: Les 5 Corps
A19: 🌿 | B19: Flore | C19: (physique) flore | D19: vs PER | F19: Tangible
A20: 🧩 | B20: Mental | C20: (mental) psy | D20: vs CON | G20: Les 5 Esprits | J20: Psyché | O20: Mémoire (x2), Puissance S, Resistance S, Perforation S, Absorption S
A21: ⚜️ | B21: Charme | K21: Psyché | O21: Malice S, Prestige
A22: ✡️ | B22: Arcane | C22: (arcanique) arcane, (force) force | D22: vs MAG | E22: Physique | F22: Intangible
A23: 🔮 | B23: Magie | G23: Magie | J23: Mana | K23: Mana | O23: Puissance M, Perforation M, Malice M
A24: 🪷 | B24: Nature | G24: Equilibre | J24: Chi | K24: Chi | O24: Résistance M, Absorption M, Intuition, Opposition
A25: ☢️ | B25: Toxique | C25: (continue) poison, sang, acide | D25: vs CON, FOR, PER | E25: Physique
A26: 🎭 | B26: Illusion | C26: (iLusoir) Illusion | D26: vs VOL | E26: Mental
A27: 📚 | B27: Savoir
A28: 👁️ | B28: Vision
A29: ⚔️ | B29: Acier | C29: (physique) acier | D29: vs DEX, FOR, AGI, CON, PER | E29: Physique | F29: Tangible
A30: 🛡️ | B30: Guerre | O30: Allonge (x1), Résistance (x1), Pénétration (x1), Jet critique (x2) | P30: Allonge (x1), Résistance (x1), Pénétration (x1), Jet critique (x2)
A31: 💢 | B31: Vide | C31: (origine) gravité | D31: vs EQU | E31: Physique
B32: Mixte
A33: Type de mots
A34: Base | B34: Définit les mécanismes fondamentaux sur lesquels se base le sort
A35: Liaison | B35: Associé à une base, forme ou effet, en altère les effets
A36: Forme | B36: Confère une forme plus avancé à un sort, par défaut les sorts se lance au contact
A37: Effet | B37: Définit l'effet du sort, au moins un effet est nécessaire
A38: Clé | B38: Précise un élément clé d'un effet de sort, se rattache donc forcément à un effet
A40: Un test d'incantation se confronte à la difficulté d'un sort
A41: Un sort a une difficulté basé sur la difficulté de sa base + les difficultés des autres mots
...

Sheet Idées
B2: Bénédiction qui a x% (magnitude) d'éviter la magie
B3: Animation d'arme (si elle est dans les mains d'un individus alors il y a un test de sauvegarde)
B4: Magie restraure un membre perdu
B5: La cible peux se statufier à volonté (pour s'endurcir ou passer inaperçu)
B6: Renvoie des projectiles x%
B7: Entendre les pensées superficielles environnantes
B8: La cible ne peux pas être attaquée | E8: Dans la zone on ne peux pas attaquer
B9: La cible ne peux pas être défendue | E9: Dans la zone on ne peux pas se défendre
B10: La cible ne peux pas se mouvoir | E10: Dans la zone on ne peux pas se déplacer
B11: Réduit la qualité d'un objet
B12: Sommeil (réveil si incident)
B13: Prédestination : Buff de l'arme contre une cible unique
B14: Séisme : dégats sur objets/structures, x tests de solidités ?
B15: imperméabilité totale (invisible à tous les sens) vs un type de cible donné
B16: La cible "pu" et inflige des pénalités à tous les individus alentours sauf si test robu réussis (pénalités réduites ?)
B17: Début du round : test de réflexes ou perte de x actions S
B18: Chaque action réalisée a x% de chance de perdre l'action
B19: Chaque action réalisée a x% de chance de ne pas consommer d'action (ou rendre ACTS ?)
B20: Achève une créature qui a moins de x PV / PS
B21: Champs de force qui empêche d'approcher/dépasser, peux être forcé via test approprié de muscu réussis
B22: Maladie + via toxique
... B37: Ench qui permet de lock une porte à ceux qui ont pas le mdp

Sheet Linguistique
A1: Structure linguistique magique :
B2: Préfixes = écoles (le moyen)
B3: Racines = effets (le quoi)
B4: Suffixes = domaines (le comment)
B5: « J’agis par [École], pour [Effet], sur [Domaine]. »
A7: École | B7: Lettre-clé | C7: Préfixes (4 variantes) | E7: Phonétique / Sens | H7: Symbole
A8: Destruction | C8: Ka-, Kor-, Kra-, Kru- | D8: Kel-, Kin- | E8: Sec, dur, explosif — frappe, brise, pulvérise | H8: ✸
A9: Restauration | C9: Re-, Ren-, Ras-, Rho- | D9: Rel-, Ryu- | E9: Doux, fluide, réparateur — soigne, restaure | H9: ⌖
A10: Bénédiction | C10: Lu-, Lux-, Lem-, Lir- | D10: Lok-, Lyn- | E10: Clair, lumineux, pur — élève, éclaire | H10: ✧
A11: Malédiction | C11: Mal-, Mor-, Mug-, Mun- | D11: Maz-, Myd- | E11: Grave, sombre, guttural — corrompt, oppresse | H11: ⧖
A12: Invocation | C12: Vo-, Van-, Vor-, Vas- | D12: Vel-, Vyn- | E12: Appel, convocation, souffle vital — fait venir | H12: ✪
A13: Abjuration | C13: Bar-, Bel-, Bas-, Bren- | D13: Bor-, Bri- | E13: Tranchant, protecteur, ferme — bloque, nie | H13: ⛊
A14: Divination | C14: Di-, Dor-, Del-, Dar- | D14: Den-, Dra- | E14: Clair, observant, précis — perçoit, révèle | H14: ⊙
A15: Évocation | C15: Ev-, En-, Elo-, Eru- | D15: Ekl-, Etr- | E15: Énergique, jaillissant — exprime, manifeste | H15: ⧉
A16: Conjuration | C16: Con-, Cen-, Col-, Car- | D16: Cym-, Cal- | E16: Formel, rituel, lié — lie, invoque, rassemble | H16: ⧗
A17: Altération | C17: Al-, Ar-, As-, Aen- | D17: Aka-, Atr- | E17: Malléable, mouvant, changeant — transforme | H17: ≈
A19: Domaine | B19: Suffixe | C19: Sens / texture sonore
A20: Feu | B20: -ar | C20: vif, sec, ardent
A21: Glace | B21: -is | C21: tranchant, froid
A22: Foudre | B22: -or | C22: claquant, électrique
A23: Terre | B23: -um | C23: massif, solide
A24: Eau | B24: -yn | C24: fluide, doux
A25: Air | B25: -el | C25: aérien, léger
A26: Lumière | B26: -ion | C26: pur, céleste
A27: Ombre | B27: -oth | C27: grave, mystérieux
A28: Loi | B28: -em | C28: structuré, rigide
A29: Chaos | B29: -ix | C29: erratique, fluide
A30: Sacre | B30: -iel | C30: harmonieux, divin
... A49: Vide | B49: -arh | C49: abyssal, neutre

Sheet Stuff
A2: Focalisateurs | B2: Catégories | C2: Capacité | D2: Prix | E2: Description capacité | H2: Notes | K2: Matières en + | L2: Améliorations uniques ?
K3: de la magicite
A5: Tatouage | B5: 0 | C5: Osmose | E5: Rapidité +5, ne peux être désarmé etc | H5: Niveau maximum des sorts = qualités | K5: Sans
A6: Bâtons | B6: 2~4 | C6: Puissance | E6: Puissance du sort augmentée (de 1 par niveau du sort) | H6: Niveau maximum des sorts = qualités | K6: Metal ou Bois | L6: Perforation +2
A7: Sceptre | B7: 2~3 | C7: Maitrise | E7: Désavantages aux défenses adverses | H7: Niveau maximum des sorts = qualités | K7: Metal ou Bois
A8: Baguettes | B8: 1~2 | C8: Malice | E8: Désavantages aux sauvegardes adverses | H8: Niveau maximum des sorts = qualités | K8: Metal ou Bois
A9: Orbes | B9: 1~3 | C9: Tactique | E9: Portée des Sorts +3 | H9: Niveau maximum des sorts = qualités | K9: Minéral | L9: Les sorts de contact peuvent utiliser la portée intégrée au focalisateur à la place
A10: Totems | B10: 1~3 | C10: Lien | E10: Peux maintenir un sort sans focus | H10: Niveau maximum des sorts = qualités | K10: Bois | L10: Réduit la corruption (sur la cible) du sort maintenue de 1 par améliorations
A11: Kriss | B11: 1~3 | C11: Versatile | E11: Considéré comme un focalisateur ET une arme de mếlée | H11: Niveau maximum des sorts = qualités | K11: Metal | L11: Opp désavantagée (si cast)
A12: Grimoire | B12: 1~3 | C12: Catalogue | E12: Peux contenir (pour usage) jusqu'à 4 sorts | H12: Niveau maximum des sorts = qualités | K12: n/a | L12: Deux sorts de plus par améliorations
A13: Focus | B13: 1~3 | C13: Stockage | E13: Peux stocker (pour lancer en ACTS) jusqu'à 2 sorts | H13: Niveau maximum des sorts = qualités | K13: Metal ou Bois | L13: Un sort de plus par améliorations
A14: Talisman | B14: 1~2 | C14: Optimisation | E14: Réduit jusquà 2 le drain minimum des sorts, le drain minimum ne peux être inférieur à 2 (ce qui est 1 en deça de la règle de base) | H14: Niveau maximum des sorts = qualités | K14: Metal
A15: Canne | B15: 2~4 | C15: Arcanes | E15: Difficultés & Tests arcaniques +2 | H15: Niveau maximum des sorts = qualités | K15: Metal
A16: Abraxas | B16: 1~3 | C16: Symbiose | E16: Les soins produisent 2 points de fatigue de moins | H16: Niveau maximum des sorts = qualités | K16: Metal
A17: Charme | B17: 1~3 | C17: Conteneur | E17: Considéré comme un focalisateur ET un catalyseur (contient des sorts prédéfinies) | H17: Niveau maximum des sorts = qualités | K17: Metal ou Bois
A18: Gantelet | B18: 1~2 | C18: Rapidité | E18: Temps de cast réduit (de 1 par niveau du sort) | H18: Niveau maximum des sorts = qualités | K18: Metal ou Tissu

Sheet Rules
D1: Moitié puis moitié puis moitié = 100+50+50+50 = 250%
A3: Enchantement de lieu | D3: De base la zone d'effet est de une case, il faut donc octroyer une zone à cet effet pour l'étendre, la cible est toujours un point dans l'espace (généralement sur le sol)
A5: Mur (élémentaire)
A6: Mur (tous) | D6: Un mur peux être placé de façon longiligne ou en cercle
A7: Mur Tangible | D7: Le mur peux être détruit et ne peux être traversé, il fait (sauf contre indications) alors [Magnitude/4] cases, la catégorie de la structure dépends du type de mur, bloque la vision
A8: Mur Intangible | D8: Le mur ne peux être détruit sauf via un élément opposé, peux être traversé, il fait (sauf contre indications) alors [Magnitude/2] cases, gêne la vision mais ne la bloque pas, considéré comme un couvert de 2 pour les tirs passant à travers, les effets sont déclanchés une fois par cible lorsque cette dernière entre dans une case ou débute son tour dedans, les dégats sont considérés comme des dégats de zone
D9: Sauf si préciser les effets sont appliqués avec [Magnitude]
D10: Si une cible subit plusieurs fois les effets d'un sol, chaques nouvelles instances augmente l'effet initial de 1/4 (et subit en une fois)
D12: Mur
A13: Intangible | B13: 🔥 | C13: Feu (feu) | D13: Provoque des dégats physiques (feu) et la condition brûlure
A14: Solide | B14: 🔥 | C14: Feu (magma) | D14: Structure de catégorie [Magnitude/8], chaque attaque reçu inflige la condition brûlure avec [Magnitude/2]
A15: Intangible | B15: ❄️ | C15: Froid (froid) | D15: Provoque des dégats physiques (froid) et la condition gel
A16: Solide | B16: ❄️ | C16: Froid (glace) | D16: Structure de catégorie [Magnitude/8], chaque attaque reçu inflige la condition gel avec [Magnitude/2]
A17: Intangible | B17: ⚡ | C17: Foudre | D17: Provoque des dégats physiques (elec) et la condition paralysie
A18: Solide | B18: 🪨 | C18: Terre | D18: Structure de catégorie [Magnitude/6], taille réduite à [Magnitude/6] cases
A19: Intangible | B19: 💧 | C19: Eau | D19: Agit comme l'action tactique de renversement avec un jet de [Magnitude]
A20: Intangible | B20: 🌪️ | C20: Air | D20: Agit comme l'action tactique de repoussement avec un jet de [Magnitude]
A21: Intangible | B21: ☀️ | C21: Lumière | D21: Provoque la condition aveugle sous sa forme avancée, bloque la vision, le couvert est de 5 à la place
A22: Intangible | B22: 🌑 | C22: Ombre | D22: Provoque la condition aveugle sous sa forme avancée, bloque la vision, le couvert est de 5 à la place
A23: Intangible | B23: ⚖️ | C23: Loi
A24: Intangible | B24: 🌀 | C24: Chaos | D24: Provoque deux conditions aléatoires (issus de la liste globale des conditions)
A25: Intangible | B25: ✨ | C25: Sacre | D25: Provoque des dégats physiques (sacré), de plus la cible subit des dégats d'attrition de [Magnitude/3]
A26: Intangible | B26: 🩸 | C26: Impie | D26: Provoque des dégats physiques (sacré), de plus la cible subit des dégats mortels de [Magnitude/4]
A27: Intangible | B27: ❤️ | C27: Vie | D27: Provoque [Magnitude] dégats physiques transperçant (vie), n'affecte que les créatures faible à cet élément (mort vivant compris)
A28: Solide | B28: ☠️ | C28: Mort | D28: Structure de catégorie [Magnitude/10], le mur régénère son intégrité de [Magnitude/2] à chaque rounds
A29: Solide | B29: 🌿 | C29: Flore (ronces) | D29: Structure de catégorie [Magnitude/10], chaque attaque reçu inflige [Magnitude/2] de dégats physique (flore)
A30: Solide | B30: 🌿 | C30: Flore (fleurs) | D30: Structure de catégorie [Magnitude/12], chaque attaque reçu inflige la condition "Spore" et "Poison"
A31: Intangible | B31: ✡️ | C31: Arcane | D31: Les sorts qui passent à travers ce mur (même par manifestation) sont augmentés de [Magnitude/5] dans un sens et réduit dans l'autre OU sont augmentés de [Magnitude/3] quelques soit le sens OU sont réduits de [Magnitude/3] quelques soit le sens, au choix du lanceur de sort
A32: Intangible | B32: 🎭 | C32: Illusion | D32: Provoque des dégats mentaux (illusion) et la condition confusion
A33: Solide | B33: ⚔️ | C33: Acier (lisse) | D33: Structure de catégorie [Magnitude/5], taille réduite à [Magnitude/8] cases, les outils subissent également un test de solidité si utilisés contre ce mur, les armes subissent en prime un désavantage à ces tests
A34: Solide | B34: ⚔️ | C34: Acier (lame) | D34: Structure de catégorie [Magnitude/5], taille réduite à [Magnitude/8] cases, chaque attaque reçu inflige des dégats physiques de [Magnitude/4], chaque attaque reçu inflige la condition saignement avec [Magnitude/4]
A35: Intangible | B35: 💢 | C35: Vide | D35: Le mur ne génère pas de couverture dans un sens (choisis au lancement) et impose une couverture augmentée de [Magnitude/6] dans l'autre
A37: Sol (élémentaire)
A38: Sol (tous) | D38: Un sol peux être placé de façon libre mais nécessairement concentrique (et à peu près répartie uniformément, en tout cas pas sous forme de ligne)
A39: Sol tangible | D39: Le sol peux est considéré comme un terrain difficile, il fait alors [Magnitude/2] cases
A40: Sol intangible | D40: Le sol n'est pas un terrain difficile, il fait alors [Magnitude] cases
D41: Sauf si préciser les effets sont appliqués avec [Magnitude/2]
D42: Si une cible subit plusieurs fois les effets d'un sol, chaques nouvelles instances augmente l'effet initial de 1/4 (et subit en une fois)
D43: Il est évidemment possible de "sauter" par dessus une surface afin de réduire la zone d'exposition en la traversant (voir les règles de sauts)
D44: Tous les effets sont modifiés par un test de réflexe (de la façon prévu par les règles de base), ce test est désavantagé si la cible est au sol ou mise au sol
...

Sheet Stats
D1: TODO : ajouter la Guerre sur les stats (je l'ai fait uniquement sur le premier tableau, c'était simple, les autres j'ai pas trop eu le temps de comprendre la formule), sachant que Guerre est en SAG/VOL et Acier VOL/RUS désormais
D2: ★ / 2 | E2: ★ / 2 | F2: ★ / 3 | G2: ★ / 4 | H2: ★ / 4 | I2: ★ / 4 | J2: ★ / 1 | K2: ★ / 2 | L2: ★ / 4 | M2: ★ / 3
A3: Colonne 1 | B3: Domaine | C3: Total | D3: Destruction | E3: Restauration | F3: Evocation | G3: Abjuration | H3: Bénédiction | I3: Malédiction | J3: Invocation | K3: Divination | L3: Conjuration | M3: Altération | N3: Liaison | O3: Total 2
A4: 🧠 | B4: Esprit | C4: =Sum(D4:N4) | D4: =COUNTIF(Dest!I:I,CONCAT(CONCAT("*",A4),"*")) | E4: =COUNTIF(Rest!$I:$I,CONCAT(CONCAT("*",$A4),"*")) | F4: =COUNTIF(Evoc!$I:$I,CONCAT(CONCAT("*",$A4),"*")) | G4: =COUNTIF(Abju!$I:$I,CONCAT(CONCAT("*",$A4),"*")) | H4: =COUNTIF('Béné'!$I:$I,CONCAT(CONCAT("*",$A4),"*")) | I4: =COUNTIF('Malé'!$I:$I,CONCAT(CONCAT("*",$A4),"*")) | J4: =COUNTIF(Invoc!$I:$I,CONCAT(CONCAT("*",$A4),"*")) | K4: =COUNTIF(Divi!$I:$I,CONCAT(CONCAT("*",$A4),"*")) | L4: =COUNTIF(Conj!$I:$I,CONCAT(CONCAT("*",$A4),"*")) | M4: =COUNTIF('Alté'!$I:$I,CONCAT(CONCAT("*",$A4),"*")) | N4: =COUNTIF(L!$G:$G,CONCAT(CONCAT("*",$A4),"*")) | O4: =SUM(D4:M4)
A5: ⚕️ | B5: Corps | C5: =Sum(D5:N5) | D5: =COUNTIF(Dest!I:I,CONCAT(CONCAT("*",A5),"*")) | E5: =COUNTIF(Rest!$I:$I,CONCAT(CONCAT("*",$A5),"*")) | F5: =COUNTIF(Evoc!$I:$I,CONCAT(CONCAT("*",$A5),"*")) | G5: =COUNTIF(Abju!$I:$I,CONCAT(CONCAT("*",$A5),"*")) | H5: =COUNTIF('Béné'!$I:$I,CONCAT(CONCAT("*",$A5),"*")) | I5: =COUNTIF('Malé'!$I:$I,CONCAT(CONCAT("*",$A5),"*")) | J5: =COUNTIF(Invoc!$I:$I,CONCAT(CONCAT("*",$A5),"*")) | K5: =COUNTIF(Divi!$I:$I,CONCAT(CONCAT("*",$A5),"*")) | L5: =COUNTIF(Conj!$I:$I,CONCAT(CONCAT("*",$A5),"*")) | M5: =COUNTIF('Alté'!$I:$I,CONCAT(CONCAT("*",$A5),"*")) | N5: =COUNTIF(L!$G:$G,CONCAT(CONCAT("*",$A5),"*")) | O5: =SUM(D5:M5)
A6: 🎭 | B6: Illusion | C6: =Sum(D6:N6) | D6: =COUNTIF(Dest!I:I,CONCAT(CONCAT("*",A6),"*")) | E6: =COUNTIF(Rest!$I:$I,CONCAT(CONCAT("*",$A6),"*")) | F6: =COUNTIF(Evoc!$I:$I,CONCAT(CONCAT("*",$A6),"*")) | G6: =COUNTIF(Abju!$I:$I,CONCAT(CONCAT("*",$A6),"*")) | H6: =COUNTIF('Béné'!$I:$I,CONCAT(CONCAT("*",$A6),"*")) | I6: =COUNTIF('Malé'!$I:$I,CONCAT(CONCAT("*",$A6),"*")) | J6: =COUNTIF(Invoc!$I:$I,CONCAT(CONCAT("*",$A6),"*")) | K6: =COUNTIF(Divi!$I:$I,CONCAT(CONCAT("*",$A6),"*")) | L6: =COUNTIF(Conj!$I:$I,CONCAT(CONCAT("*",$A6),"*")) | M6: =COUNTIF('Alté'!$I:$I,CONCAT(CONCAT("*",$A6),"*")) | N6: =COUNTIF(L!$G:$G,CONCAT(CONCAT("*",$A6),"*")) | O6: =SUM(D6:M6)
A7: 🛡️ | B7: Guerre | C7: =Sum(D7:N7) | D7: =COUNTIF(Dest!I:I,CONCAT(CONCAT("*",A7),"*")) | E7: =COUNTIF(Rest!$I:$I,CONCAT(CONCAT("*",$A7),"*")) | F7: =COUNTIF(Evoc!$I:$I,CONCAT(CONCAT("*",$A7),"*")) | G7: =COUNTIF(Abju!$I:$I,CONCAT(CONCAT("*",$A7),"*")) | H7: =COUNTIF('Béné'!$I:$I,CONCAT(CONCAT("*",$A7),"*")) | I7: =COUNTIF('Malé'!$I:$I,CONCAT(CONCAT("*",$A7),"*")) | J7: =COUNTIF(Invoc!$I:$I,CONCAT(CONCAT("*",$A7),"*")) | K7: =COUNTIF(Divi!$I:$I,CONCAT(CONCAT("*",$A7),"*")) | L7: =COUNTIF(Conj!$I:$I,CONCAT(CONCAT("*",$A7),"*")) | M7: =COUNTIF('Alté'!$I:$I,CONCAT(CONCAT("*",$A7),"*")) | N7: =COUNTIF(L!$G:$G,CONCAT(CONCAT("*",$A7),"*")) | O7: =SUM(D7:M7)
A8: 🐗 | B8: Faune | C8: =Sum(D8:N8) | D8: =COUNTIF(Dest!I:I,CONCAT(CONCAT("*",A8),"*")) | E8: =COUNTIF(Rest!$I:$I,CONCAT(CONCAT("*",$A8),"*")) | F8: =COUNTIF(Evoc!$I:$I,CONCAT(CONCAT("*",$A8),"*")) | G8: =COUNTIF(Abju!$I:$I,CONCAT(CONCAT("*",$A8),"*")) | H8: =COUNTIF('Béné'!$I:$I,CONCAT(CONCAT("*",$A8),"*")) | I8: =COUNTIF('Malé'!$I:$I,CONCAT(CONCAT("*",$A8),"*")) | J8: =COUNTIF(Invoc!$I:$I,CONCAT(CONCAT("*",$A8),"*")) | K8: =COUNTIF(Divi!$I:$I,CONCAT(CONCAT("*",$A8),"*")) | L8: =COUNTIF(Conj!$I:$I,CONCAT(CONCAT("*",$A8),"*")) | M8: =COUNTIF('Alté'!$I:$I,CONCAT(CONCAT("*",$A8),"*")) | N8: =COUNTIF(L!$G:$G,CONCAT(CONCAT("*",$A8),"*")) | O8: =SUM(D8:M8)
A9: 💧 | B9: Eau | C9: =Sum(D9:N9) | D9: =COUNTIF(Dest!I:I,CONCAT(CONCAT("*",A9),"*")) | E9: =COUNTIF(Rest!$I:$I,CONCAT(CONCAT("*",$A9),"*")) | F9: =COUNTIF(Evoc!$I:$I,CONCAT(CONCAT("*",$A9),"*")) | G9: =COUNTIF(Abju!$I:$I,CONCAT(CONCAT("*",$A9),"*")) | H9: =COUNTIF('Béné'!$I:$I,CONCAT(CONCAT("*",$A9),"*")) | I9: =COUNTIF('Malé'!$I:$I,CONCAT(CONCAT("*",$A9),"*")) | J9: =COUNTIF(Invoc!$I:$I,CONCAT(CONCAT("*",$A9),"*")) | K9: =COUNTIF(Divi!$I:$I,CONCAT(CONCAT("*",$A9),"*")) | L9: =COUNTIF(Conj!$I:$I,CONCAT(CONCAT("*",$A9),"*")) | M9: =COUNTIF('Alté'!$I:$I,CONCAT(CONCAT("*",$A9),"*")) | N9: =COUNTIF(L!$G:$G,CONCAT(CONCAT("*",$A9),"*")) | O9: =SUM(D9:M9)
A10: ✨ | B10: Sacre | C10: =Sum(D10:N10) | D10: =COUNTIF(Dest!I:I,CONCAT(CONCAT("*",A10),"*")) | E10: =COUNTIF(Rest!$I:$I,CONCAT(CONCAT("*",$A10),"*")) | F10: =COUNTIF(Evoc!$I:$I,CONCAT(CONCAT("*",$A10),"*")) | G10: =COUNTIF(Abju!$I:$I,CONCAT(CONCAT("*",$A10),"*")) | H10: =COUNTIF('Béné'!$I:$I,CONCAT(CONCAT("*",$A10),"*")) | I10: =COUNTIF('Malé'!$I:$I,CONCAT(CONCAT("*",$A10),"*")) | J10: =COUNTIF(Invoc!$I:$I,CONCAT(CONCAT("*",$A10),"*")) | K10: =COUNTIF(Divi!$I:$I,CONCAT(CONCAT("*",$A10),"*")) | L10: =COUNTIF(Conj!$I:$I,CONCAT(CONCAT("*",$A10),"*")) | M10: =COUNTIF('Alté'!$I:$I,CONCAT(CONCAT("*",$A10),"*")) | N10: =COUNTIF(L!$G:$G,CONCAT(CONCAT("*",$A10),"*")) | O10: =SUM(D10:M10)
A11: 🌑 | B11: Ombre | C11: =Sum(D11:N11) | D11: =COUNTIF(Dest!I:I,CONCAT(CONCAT("*",A11),"*")) | E11: =COUNTIF(Rest!$I:$I,CONCAT(CONCAT("*",$A11),"*")) | F11: =COUNTIF(Evoc!$I:$I,CONCAT(CONCAT("*",$A11),"*")) | G11: =COUNTIF(Abju!$I:$I,CONCAT(CONCAT("*",$A11),"*")) | H11: =COUNTIF('Béné'!$I:$I,CONCAT(CONCAT("*",$A11),"*")) | I11: =COUNTIF('Malé'!$I:$I,CONCAT(CONCAT("*",$A11),"*")) | J11: =COUNTIF(Invoc!$I:$I,CONCAT(CONCAT("*",$A11),"*")) | K11: =COUNTIF(Divi!$I:$I,CONCAT(CONCAT("*",$A11),"*")) | L11: =COUNTIF(Conj!$I:$I,CONCAT(CONCAT("*",$A11),"*")) | M11: =COUNTIF('Alté'!$I:$I,CONCAT(CONCAT("*",$A11),"*")) | N11: =COUNTIF(L!$G:$G,CONCAT(CONCAT("*",$A11),"*")) | O11: =SUM(D11:M11)
A12: ⚡ | B12: Foudre | C12: =Sum(D12:N12) | D12: =COUNTIF(Dest!I:I,CONCAT(CONCAT("*",A12),"*")) | E12: =COUNTIF(Rest!$I:$I,CONCAT(CONCAT("*",$A12),"*")) | F12: =COUNTIF(Evoc!$I:$I,CONCAT(CONCAT("*",$A12),"*")) | G12: =COUNTIF(Abju!$I:$I,CONCAT(CONCAT("*",$A12),"*")) | H12: =COUNTIF('Béné'!$I:$I,CONCAT(CONCAT("*",$A12),"*")) | I12: =COUNTIF('Malé'!$I:$I,CONCAT(CONCAT("*",$A12),"*")) | J12: =COUNTIF(Invoc!$I:$I,CONCAT(CONCAT("*",$A12),"*")) | K12: =COUNTIF(Divi!$I:$I,CONCAT(CONCAT("*",$A12),"*")) | L12: =COUNTIF(Conj!$I:$I,CONCAT(CONCAT("*",$A12),"*")) | M12: =COUNTIF('Alté'!$I:$I,CONCAT(CONCAT("*",$A12),"*")) | N12: =COUNTIF(L!$G:$G,CONCAT(CONCAT("*",$A12),"*")) | O12: =SUM(D12:M12)
A13: ❄️ | B13: Glace | C13: =Sum(D13:N13) | D13: =COUNTIF(Dest!I:I,CONCAT(CONCAT("*",A13),"*")) | E13: =COUNTIF(Rest!$I:$I,CONCAT(CONCAT("*",$A13),"*")) | F13: =COUNTIF(Evoc!$I:$I,CONCAT(CONCAT("*",$A13),"*")) | G13: =COUNTIF(Abju!$I:$I,CONCAT(CONCAT("*",$A13),"*")) | H13: =COUNTIF('Béné'!$I:$I,CONCAT(CONCAT("*",$A13),"*")) | I13: =COUNTIF('Malé'!$I:$I,CONCAT(CONCAT("*",$A13),"*")) | J13: =COUNTIF(Invoc!$I:$I,CONCAT(CONCAT("*",$A13),"*")) | K13: =COUNTIF(Divi!$I:$I,CONCAT(CONCAT("*",$A13),"*")) | L13: =COUNTIF(Conj!$I:$I,CONCAT(CONCAT("*",$A13),"*")) | M13: =COUNTIF('Alté'!$I:$I,CONCAT(CONCAT("*",$A13),"*")) | N13: =COUNTIF(L!$G:$G,CONCAT(CONCAT("*",$A13),"*")) | O13: =SUM(D13:M13)
A14: 📚 | B14: Savoir | C14: =Sum(D14:N14) | D14: =COUNTIF(Dest!I:I,CONCAT(CONCAT("*",A14),"*")) | E14: =COUNTIF(Rest!$I:$I,CONCAT(CONCAT("*",$A14),"*")) | F14: =COUNTIF(Evoc!$I:$I,CONCAT(CONCAT("*",$A14),"*")) | G14: =COUNTIF(Abju!$I:$I,CONCAT(CONCAT("*",$A14),"*")) | H14: =COUNTIF('Béné'!$I:$I,CONCAT(CONCAT("*",$A14),"*")) | I14: =COUNTIF('Malé'!$I:$I,CONCAT(CONCAT("*",$A14),"*")) | J14: =COUNTIF(Invoc!$I:$I,CONCAT(CONCAT("*",$A14),"*")) | K14: =COUNTIF(Divi!$I:$I,CONCAT(CONCAT("*",$A14),"*")) | L14: =COUNTIF(Conj!$I:$I,CONCAT(CONCAT("*",$A14),"*")) | M14: =COUNTIF('Alté'!$I:$I,CONCAT(CONCAT("*",$A14),"*")) | N14: =COUNTIF(L!$G:$G,CONCAT(CONCAT("*",$A14),"*")) | O14: =SUM(D14:M14)
A15: 🔥 | B15: Feu | C15: =Sum(D15:N15) | D15: =COUNTIF(Dest!I:I,CONCAT(CONCAT("*",A15),"*")) | E15: =COUNTIF(Rest!$I:$I,CONCAT(CONCAT("*",$A15),"*")) | F15: =COUNTIF(Evoc!$I:$I,CONCAT(CONCAT("*",$A15),"*")) | G15: =COUNTIF(Abju!$I:$I,CONCAT(CONCAT("*",$A15),"*")) | H15: =COUNTIF('Béné'!$I:$I,CONCAT(CONCAT("*",$A15),"*")) | I15: =COUNTIF('Malé'!$I:$I,CONCAT(CONCAT("*",$A15),"*")) | J15: =COUNTIF(Invoc!$I:$I,CONCAT(CONCAT("*",$A15),"*")) | K15: =COUNTIF(Divi!$I:$I,CONCAT(CONCAT("*",$A15),"*")) | L15: =COUNTIF(Conj!$I:$I,CONCAT(CONCAT("*",$A15),"*")) | M15: =COUNTIF('Alté'!$I:$I,CONCAT(CONCAT("*",$A15),"*")) | N15: =COUNTIF(L!$G:$G,CONCAT(CONCAT("*",$A15),"*")) | O15: =SUM(D15:M15)
... A33: ☠️ | B33: Mort | C33: =Sum(D33:N33) | D33: =COUNTIF(Dest!I:I,CONCAT(CONCAT("*",A33),"*")) | E33: =COUNTIF(Rest!$I:$I,CONCAT(CONCAT("*",$A33),"*")) | F33: =COUNTIF(Evoc!$I:$I,CONCAT(CONCAT("*",$A33),"*")) | G33: =COUNTIF(Abju!$I:$I,CONCAT(CONCAT("*",$A33),"*")) | H33: =COUNTIF('Béné'!$I:$I,CONCAT(CONCAT("*",$A33),"*")) | I33: =COUNTIF('Malé'!$I:$I,CONCAT(CONCAT("*",$A33),"*")) | J33: =COUNTIF(Invoc!$I:$I,CONCAT(CONCAT("*",$A33),"*")) | K33: =COUNTIF(Divi!$I:$I,CONCAT(CONCAT("*",$A33),"*")) | L33: =COUNTIF(Conj!$I:$I,CONCAT(CONCAT("*",$A33),"*")) | M33: =COUNTIF('Alté'!$I:$I,CONCAT(CONCAT("*",$A33),"*")) | N33: =COUNTIF(L!$G:$G,CONCAT(CONCAT("*",$A33),"*")) | O33: =SUM(D33:M33)
B34: Total | C34: =Sum(D34:N34) | D34: =SUM(D3:D33) | E34: =SUM(E3:E33) | F34: =SUM(F3:F33) | G34: =SUM(G3:G33) | H34: =SUM(H3:H33) | I34: =SUM(I3:I33) | J34: =SUM(J3:J33) | K34: =SUM(K3:K33) | ... M34: =SUM(M3:M33) | N34: =COUNTIF(L!$G:$G,CONCAT(CONCAT("*",$A34),"*")) | O34: =SUM(D34:M34)
B37: SAG | C37: INT | D37: VOL | E37: RUS | F37: CHA
B38: =B82+Tableau1[[#TOTALS],[SAG]] | C38: =C82+Tableau1[[#TOTALS],[INT]] | D38: =D82+Tableau1[[#TOTALS],[VOL]] | E38: =E82+Tableau1[[#TOTALS],[RUS]] | F38: =F82+Tableau1[[#TOTALS],[CHA]]
A52: Domaine | B52: SAG | C52: INT | D52: VOL | E52: RUS | F52: CHA
A53: Feu | B53: =if(LOOKUP($A53,Stats!$A$115:$A$143,Stats!B$115:B$143)=1,VLOOKUP($A53,$B$4:$C$32,2,FALSE),0) | C53: =if(LOOKUP($A53,Stats!$A$115:$A$143,Stats!C$115:C$143)=1,VLOOKUP($A53,$B$4:$C$33,2,FALSE),0) | D53: =if(LOOKUP($A53,Stats!$A$115:$A$143,Stats!D$115:D$143)=1,VLOOKUP($A53,$B$4:$C$32,2,FALSE),0) | E53: =if(LOOKUP($A53,Stats!$A$115:$A$143,Stats!E$115:E$143)=1,VLOOKUP($A53,$B$4:$C$33,2,FALSE),0) | F53: =if(LOOKUP($A53,Stats!$A$115:$A$143,Stats!F$115:F$143)=1,VLOOKUP($A53,$B$4:$C$32,2,FALSE),0)
A54: Glace | B54: =if(LOOKUP($A54,Stats!$A$115:$A$143,Stats!B$115:B$143)=1,VLOOKUP($A54,$B$4:$C$32,2,FALSE),0) | C54: =if(LOOKUP($A54,Stats!$A$115:$A$143,Stats!C$115:C$143)=1,VLOOKUP($A54,$B$4:$C$33,2,FALSE),0) | D54: =if(LOOKUP($A54,Stats!$A$115:$A$143,Stats!D$115:D$143)=1,VLOOKUP($A54,$B$4:$C$32,2,FALSE),0) | E54: =if(LOOKUP($A54,Stats!$A$115:$A$143,Stats!E$115:E$143)=1,VLOOKUP($A54,$B$4:$C$33,2,FALSE),0) | F54: =if(LOOKUP($A54,Stats!$A$115:$A$143,Stats!F$115:F$143)=1,VLOOKUP($A54,$B$4:$C$32,2,FALSE),0)
A55: Foudre | B55: =if(LOOKUP($A55,Stats!$A$115:$A$143,Stats!B$115:B$143)=1,VLOOKUP($A55,$B$4:$C$32,2,FALSE),0) | C55: =if(LOOKUP($A55,Stats!$A$115:$A$143,Stats!C$115:C$143)=1,VLOOKUP($A55,$B$4:$C$33,2,FALSE),0) | D55: =if(LOOKUP($A55,Stats!$A$115:$A$143,Stats!D$115:D$143)=1,VLOOKUP($A55,$B$4:$C$32,2,FALSE),0) | E55: =if(LOOKUP($A55,Stats!$A$115:$A$143,Stats!E$115:E$143)=1,VLOOKUP($A55,$B$4:$C$33,2,FALSE),0) | F55: =if(LOOKUP($A55,Stats!$A$115:$A$143,Stats!F$115:F$143)=1,VLOOKUP($A55,$B$4:$C$32,2,FALSE),0)
A56: Terre | B56: =if(LOOKUP($A56,Stats!$A$115:$A$143,Stats!B$115:B$143)=1,VLOOKUP($A56,$B$4:$C$32,2,FALSE),0) | C56: =if(LOOKUP($A56,Stats!$A$115:$A$143,Stats!C$115:C$143)=1,VLOOKUP($A56,$B$4:$C$33,2,FALSE),0) | D56: =if(LOOKUP($A56,Stats!$A$115:$A$143,Stats!D$115:D$143)=1,VLOOKUP($A56,$B$4:$C$32,2,FALSE),0) | E56: =if(LOOKUP($A56,Stats!$A$115:$A$143,Stats!E$115:E$143)=1,VLOOKUP($A56,$B$4:$C$33,2,FALSE),0) | F56: =if(LOOKUP($A56,Stats!$A$115:$A$143,Stats!F$115:F$143)=1,VLOOKUP($A56,$B$4:$C$32,2,FALSE),0)
A57: Eau | B57: =if(LOOKUP($A57,Stats!$A$115:$A$143,Stats!B$115:B$143)=1,VLOOKUP($A57,$B$4:$C$32,2,FALSE),0) | C57: =if(LOOKUP($A57,Stats!$A$115:$A$143,Stats!C$115:C$143)=1,VLOOKUP($A57,$B$4:$C$33,2,FALSE),0) | D57: =if(LOOKUP($A57,Stats!$A$115:$A$143,Stats!D$115:D$143)=1,VLOOKUP($A57,$B$4:$C$32,2,FALSE),0) | E57: =if(LOOKUP($A57,Stats!$A$115:$A$143,Stats!E$115:E$143)=1,VLOOKUP($A57,$B$4:$C$33,2,FALSE),0) | F57: =if(LOOKUP($A57,Stats!$A$115:$A$143,Stats!F$115:F$143)=1,VLOOKUP($A57,$B$4:$C$32,2,FALSE),0)
A58: Air | B58: =if(LOOKUP($A58,Stats!$A$115:$A$143,Stats!B$115:B$143)=1,VLOOKUP($A58,$B$4:$C$32,2,FALSE),0) | C58: =if(LOOKUP($A58,Stats!$A$115:$A$143,Stats!C$115:C$143)=1,VLOOKUP($A58,$B$4:$C$33,2,FALSE),0) | D58: =if(LOOKUP($A58,Stats!$A$115:$A$143,Stats!D$115:D$143)=1,VLOOKUP($A58,$B$4:$C$32,2,FALSE),0) | E58: =if(LOOKUP($A58,Stats!$A$115:$A$143,Stats!E$115:E$143)=1,VLOOKUP($A58,$B$4:$C$33,2,FALSE),0) | F58: =if(LOOKUP($A58,Stats!$A$115:$A$143,Stats!F$115:F$143)=1,VLOOKUP($A58,$B$4:$C$32,2,FALSE),0)
A59: Lumière | B59: =if(LOOKUP($A59,Stats!$A$115:$A$143,Stats!B$115:B$143)=1,VLOOKUP($A59,$B$4:$C$32,2,FALSE),0) | C59: =if(LOOKUP($A59,Stats!$A$115:$A$143,Stats!C$115:C$143)=1,VLOOKUP($A59,$B$4:$C$33,2,FALSE),0) | D59: =if(LOOKUP($A59,Stats!$A$115:$A$143,Stats!D$115:D$143)=1,VLOOKUP($A59,$B$4:$C$32,2,FALSE),0) | E59: =if(LOOKUP($A59,Stats!$A$115:$A$143,Stats!E$115:E$143)=1,VLOOKUP($A59,$B$4:$C$33,2,FALSE),0) | F59: =if(LOOKUP($A59,Stats!$A$115:$A$143,Stats!F$115:F$143)=1,VLOOKUP($A59,$B$4:$C$32,2,FALSE),0)
A60: Ombre | B60: =if(LOOKUP($A60,Stats!$A$115:$A$143,Stats!B$115:B$143)=1,VLOOKUP($A60,$B$4:$C$32,2,FALSE),0) | C60: =if(LOOKUP($A60,Stats!$A$115:$A$143,Stats!C$115:C$143)=1,VLOOKUP($A60,$B$4:$C$33,2,FALSE),0) | D60: =if(LOOKUP($A60,Stats!$A$115:$A$143,Stats!D$115:D$143)=1,VLOOKUP($A60,$B$4:$C$32,2,FALSE),0) | E60: =if(LOOKUP($A60,Stats!$A$115:$A$143,Stats!E$115:E$143)=1,VLOOKUP($A60,$B$4:$C$33,2,FALSE),0) | F60: =if(LOOKUP($A60,Stats!$A$115:$A$143,Stats!F$115:F$143)=1,VLOOKUP($A60,$B$4:$C$32,2,FALSE),0)
A61: Loi | B61: =if(LOOKUP($A61,Stats!$A$115:$A$143,Stats!B$115:B$143)=1,VLOOKUP($A61,$B$4:$C$32,2,FALSE),0) | C61: =if(LOOKUP($A61,Stats!$A$115:$A$143,Stats!C$115:C$143)=1,VLOOKUP($A61,$B$4:$C$33,2,FALSE),0) | D61: =if(LOOKUP($A61,Stats!$A$115:$A$143,Stats!D$115:D$143)=1,VLOOKUP($A61,$B$4:$C$32,2,FALSE),0) | E61: =if(LOOKUP($A61,Stats!$A$115:$A$143,Stats!E$115:E$143)=1,VLOOKUP($A61,$B$4:$C$33,2,FALSE),0) | F61: =if(LOOKUP($A61,Stats!$A$115:$A$143,Stats!F$115:F$143)=1,VLOOKUP($A61,$B$4:$C$32,2,FALSE),0)
A62: Chaos | B62: =if(LOOKUP($A62,Stats!$A$115:$A$143,Stats!B$115:B$143)=1,VLOOKUP($A62,$B$4:$C$32,2,FALSE),0) | C62: =if(LOOKUP($A62,Stats!$A$115:$A$143,Stats!C$115:C$143)=1,VLOOKUP($A62,$B$4:$C$33,2,FALSE),0) | D62: =if(LOOKUP($A62,Stats!$A$115:$A$143,Stats!D$115:D$143)=1,VLOOKUP($A62,$B$4:$C$32,2,FALSE),0) | E62: =if(LOOKUP($A62,Stats!$A$115:$A$143,Stats!E$115:E$143)=1,VLOOKUP($A62,$B$4:$C$33,2,FALSE),0) | F62: =if(LOOKUP($A62,Stats!$A$115:$A$143,Stats!F$115:F$143)=1,VLOOKUP($A62,$B$4:$C$32,2,FALSE),0)
A63: Sacre | B63: =if(LOOKUP($A63,Stats!$A$115:$A$143,Stats!B$115:B$143)=1,VLOOKUP($A63,$B$4:$C$32,2,FALSE),0) | C63: =if(LOOKUP($A63,Stats!$A$115:$A$143,Stats!C$115:C$143)=1,VLOOKUP($A63,$B$4:$C$33,2,FALSE),0) | D63: =if(LOOKUP($A63,Stats!$A$115:$A$143,Stats!D$115:D$143)=1,VLOOKUP($A63,$B$4:$C$32,2,FALSE),0) | E63: =if(LOOKUP($A63,Stats!$A$115:$A$143,Stats!E$115:E$143)=1,VLOOKUP($A63,$B$4:$C$33,2,FALSE),0) | F63: =if(LOOKUP($A63,Stats!$A$115:$A$143,Stats!F$115:F$143)=1,VLOOKUP($A63,$B$4:$C$32,2,FALSE),0)
A64: Impie | B64: =if(LOOKUP($A64,Stats!$A$115:$A$143,Stats!B$115:B$143)=1,VLOOKUP($A64,$B$4:$C$32,2,FALSE),0) | C64: =if(LOOKUP($A64,Stats!$A$115:$A$143,Stats!C$115:C$143)=1,VLOOKUP($A64,$B$4:$C$33,2,FALSE),0) | D64: =if(LOOKUP($A64,Stats!$A$115:$A$143,Stats!D$115:D$143)=1,VLOOKUP($A64,$B$4:$C$32,2,FALSE),0) | E64: =if(LOOKUP($A64,Stats!$A$115:$A$143,Stats!E$115:E$143)=1,VLOOKUP($A64,$B$4:$C$33,2,FALSE),0) | F64: =if(LOOKUP($A64,Stats!$A$115:$A$143,Stats!F$115:F$143)=1,VLOOKUP($A64,$B$4:$C$32,2,FALSE),0)
... A80: Acier | B80: =if(LOOKUP($A80,Stats!$A$115:$A$143,Stats!B$115:B$143)=1,VLOOKUP($A80,$B$4:$C$32,2,FALSE),0) | C80: =if(LOOKUP($A80,Stats!$A$115:$A$143,Stats!C$115:C$143)=1,VLOOKUP($A80,$B$4:$C$33,2,FALSE),0) | D80: =if(LOOKUP($A80,Stats!$A$115:$A$143,Stats!D$115:D$143)=1,VLOOKUP($A80,$B$4:$C$32,2,FALSE),0) | E80: =if(LOOKUP($A80,Stats!$A$115:$A$143,Stats!E$115:E$143)=1,VLOOKUP($A80,$B$4:$C$33,2,FALSE),0) | F80: =if(LOOKUP($A80,Stats!$A$115:$A$143,Stats!F$115:F$143)=1,VLOOKUP($A80,$B$4:$C$32,2,FALSE),0)
A81: Vide | B81: =if(LOOKUP($A81,Stats!$A$115:$A$143,Stats!B$115:B$143)=1,VLOOKUP($A81,$B$4:$C$32,2,FALSE),0) | C81: =if(LOOKUP($A81,Stats!$A$115:$A$143,Stats!C$115:C$143)=1,VLOOKUP($A81,$B$4:$C$32,2,FALSE),0) | D81: =if(LOOKUP($A81,Stats!$A$115:$A$143,Stats!D$115:D$143)=1,VLOOKUP($A81,$B$4:$C$32,2,FALSE),0) | E81: =if(LOOKUP($A81,Stats!$A$115:$A$143,Stats!E$115:E$143)=1,VLOOKUP($A81,$B$4:$C$32,2,FALSE),0) | F81: =if(LOOKUP($A81,Stats!$A$115:$A$143,Stats!F$115:F$143)=1,VLOOKUP($A81,$B$4:$C$32,2,FALSE),0)
A82: . Total | B82: =SUM(Tableau2[SAG]) | C82: =SUM(Tableau2[INT]) | D82: =SUM(Tableau2[VOL]) | E82: =SUM(Tableau2[RUS]) | F82: =SUM(Tableau2[CHA])
A85: Ecole | B85: SAG | C85: INT | D85: VOL | E85: RUS | F85: CHA
A86: Destruction | B86: =if(B100=1,$D$34,0) | C86: =if(C100=1,$D$34,0) | D86: =if(D100=1,$D$34,0) | E86: =if(E100=1,$D$34,0) | F86: =if(F100=1,$D$34,0)
A87: Restauration | B87: =if(B101=1,$E$34,0) | C87: =if(C101=1,$E$34,0) | D87: =if(D101=1,$E$34,0) | E87: =if(E101=1,$E$34,0) | F87: =if(F101=1,$E$34,0)
A88: Evocation | B88: =if(B102=1,$F$34,0) | C88: =if(C102=1,$F$34,0) | D88: =if(D102=1,$F$34,0) | E88: =if(E102=1,$F$34,0) | F88: =if(F102=1,$F$34,0)
A89: Abjuration | B89: =if(B103=1,$G$34,0) | C89: =if(C103=1,$G$34,0) | D89: =if(D103=1,$G$34,0) | E89: =if(E103=1,$G$34,0) | F89: =if(F103=1,$G$34,0)
...

Sheet Sorts
A1: Ecole/Domaine | B1: Titre | D1: Description | H1: Mot de Pouvoir (vulguaire) | I1: Clé | K1: Diffusion | L1: Propagation | M1: Structure | N1: Avancé | P1: Liaison 1 | Q1: Liaison 2 | R1: Liaison 3 | S1: Notes | T1: 2nd Mot | U1: Clé 2nd Mot | V1: Mot lié | W1: Clé lié | X1: Description (if any)
A2: Destruction | B2: Trait de Foudre | H2: =Dest!J3 | I2: ='Règles'!C158 | K2: =F!$A$4 | L2: =F!$A$11 | S2: =Dest!N3
A3: Destruction | B3: Cône de Glace | H3: =Dest!J3 | I3: ='Règles'!C157 | K3: =F!$A$3 | L3: =F!$A$17 | S3: =Dest!N3
A4: Destruction | B4: Boule de Feu | H4: =Dest!J3 | I4: ='Règles'!C156 | K4: =F!$A$4 | L4: =F!$A$11 | M4: =F!$A$27 | S4: =Dest!N3
A5: Destruction | B5: Déflagration Psychique | H5: =Dest!J7 | I5: ='Règles'!C174 | K5: =F!$A$2 | L5: =F!$A$13 | P5: =L!$A$4 | S5: =Dest!N7
A6: Destruction | B6: Doigt de Fissure | H6: =Dest!J35 | I6: ='Règles'!C159 | K6: =F!$A$3 | L6: =F!$A$11 | S6: =Dest!N35
A7: Destruction | B7: Doigt de Désintégration | H7: =Dest!J57 | I7: ='Règles'!C156 | K7: =F!$A$3 | L7: =F!$A$11 | S7: =Dest!N57
A8: Destruction | B8: Trou de Mémoire | H8: =Dest!J56 | I8: ='Règles'!C174 | K8: =F!$A$5 | L8: =F!$A$11 | S8: =Dest!N56
A9: Destruction | B9: Mot de Mort | H9: =Dest!J58 | I9: ='Règles'!C169 | K9: =F!$A$6 | L9: =F!$A$11 | S9: =Dest!N58
A10: Destruction | B10: Présage Sanglant | H10: =Dest!J65 | I10: ='Règles'!C167 | K10: =F!$A$5 | L10: =F!$A$11 | S10: =Dest!N65
A11: Destruction | B11: Myriade de Flèches Acide | D11: changer le nom ? | H11: =Dest!J18 | I11: ='Règles'!C179 | K11: =F!$A$4 | L11: =F!$A$11 | M11: =F!$A$38 | S11: =Dest!N18
A12: Destruction | B12: Oeil du Cyclone | H12: =Dest!J16 | I12: ='Règles'!C161 | K12: =F!$A$2 | L12: =F!$A$13 | P12: =L!$A$4 | S12: =Dest!N16
A13: Destruction | B13: Flèche de Feu | H13: =Dest!J3 | I13: ='Règles'!C158 | K13: =F!$A$4 | L13: =F!$A$11 | P13: =L!$A$3 | S13: =Dest!N3
A14: Restauration | B14: Soin du corps | H14: =Rest!J3 | I14: ='Règles'!C168 | K14: =F!$A$5 | L14: =F!$A$11 | S14: =Rest!N3
A15: Restauration | B15: Soin de l'esprit | H15: =Rest!J3 | I15: ='Règles'!C174 | K15: =F!$A$5 | L15: =F!$A$11 | S15: =Rest!N3
A16: Restauration | B16: Soin d'endurance | H16: =Rest!J5 | I16: ='Règles'!C178 | K16: =F!$A$5 | L16: =F!$A$11 | S16: =Rest!N5
A17: Restauration | B17: Cercle de soin | H17: =Rest!J3 | I17: ='Règles'!C168 | K17: =F!$A$2 | L17: =F!$A$18 | S17: =Rest!N3
A18: Restauration | B18: Remède Universel | H18: =Rest!J13 | I18: ='Règles'!C170 | K18: =F!$A$5 | L18: =F!$A$11 | N18: =A!A3 | P18: =L!A6 | S18: Le même mot est utilisé deux fois : Une fois pour le corps, une fois pour l'esprit | T18: =Rest!J13 | U18: 🧠 Esprit: Rasneutays
A19: Restauration | B19: Soin des blessures | H19: =Rest!J19 | I19: ='Règles'!C170 | K19: =F!$A$5 | L19: =F!$A$11 | S19: =Rest!N19
A20: Restauration | B20: Retour à la Vie | H20: =Rest!J21 | I20: ='Règles'!C168 | K20: =F!$A$5 | L20: =F!$A$11 | S20: =Rest!N21
A21: Restauration | B21: Don de Régénération | H21: =Rest!J33 | I21: ='Règles'!C168 | K21: =F!$A$5 | L21: =F!$A$11 | S21: =Rest!N33
A22: Restauration | B22: Premiers Soins | H22: =Rest!J29 | I22: ='Règles'!C168 | K22: =F!$A$5 | L22: =F!$A$11 | S22: =Rest!N29
A23: Restauration | B23: Illusion des Grandeurs | H23: =Rest!J8 | I23: ='Règles'!C180 | K23: =F!$A$5 | L23: =F!$A$11 | S23: =Rest!N8
A24: Restauration | B24: Sanctuaire | H24: =Rest!J5 | I24: ='Règles'!C178 | K24: =F!$A$5 | L24: =F!$A$18 | M24: =F!$A$24 | P24: =L!$A$4 | S24: =Rest!N5
A25: Bénédiction | B25: Croissance Physique | H25: ='Béné'!J52 | I25: ⚕️ Corps: Luxlevoen | K25: =F!$A$5 | L25: =F!$A$11 | S25: ='Béné'!N53
A26: Bénédiction | B26: Croissance Mentale | H26: ='Béné'!J52 | I26: 🧠 Esprit: Luxlevoys | K26: =F!$A$5 | L26: =F!$A$11 | S26: ='Béné'!N53
A27: Bénédiction | B27: Surcroissance Bestiale | H27: ='Béné'!J54 | I27: ='Règles'!C172 | K27: =F!$A$5 | L27: =F!$A$11 | S27: ='Béné'!N54
A28: Bénédiction | B28: Surcroissance Spirituelle | H28: ='Béné'!J55 | I28: ='Règles'!C174 | K28: =F!$A$5 | L28: =F!$A$11 | S28: ='Béné'!N55
A29: Bénédiction | B29: Amplification des Instincts | H29: ='Béné'!J44 | I29: ='Règles'!C178 | K29: =F!$A$5 | L29: =F!$A$11 | S29: ='Béné'!N69
A30: Bénédiction | B30: Bénédiction des Justes | H30: ='Béné'!J113 | I30: ='Règles'!C166 | K30: =F!$A$5 | L30: =F!$A$11 | S30: ='Béné'!N113
A31: Bénédiction | B31: Protection Physique | H31: ='Béné'!J123 | I31: ='Règles'!C184 | K31: =F!$A$5 | L31: =F!$A$11 | S31: ='Béné'!N123
A32: Bénédiction | B32: Célérité des Vents | H32: ='Béné'!J127 | I32: ='Règles'!C161 | K32: =F!$A$5 | L32: =F!$A$11 | S32: ='Béné'!N127
A33: Bénédiction | B33: Echos de la Guerre | H33: ='Béné'!J153 | I33: ='Règles'!C184 | K33: =F!$A$5 | L33: =F!$A$11 | S33: ='Béné'!N153
A34: Bénédiction | B34: Alléger le Fardeau | H34: ='Béné'!J166 | I34: ='Règles'!C178 | K34: =F!$A$5 | L34: =F!$A$11 | S34: ='Béné'!N166
A35: Malédiction | B35: Affaiblissement du Corps | H35: ='Malé'!J70 | I35: ='Règles'!C170 | K35: =F!$A$5 | L35: =F!$A$11 | S35: ='Malé'!N70
A36: Malédiction | B36: Dépérissement de l'Esprit | H36: ='Malé'!J70 | I36: ='Règles'!C171 | K36: =F!$A$5 | L36: =F!$A$11 | S36: ='Malé'!N70
A37: Malédiction | B37: Rayon de Vulnérabilité | H37: ='Malé'!J22 | I37: ='Règles'!C169 | K37: =F!$A$5 | L37: =F!$A$11 | S37: ='Malé'!N22
A38: Malédiction | B38: Mauvais Présage | H38: ='Malé'!J29 | I38: ='Règles'!C167 | K38: =F!$A$5 | L38: =F!$A$11 | S38: ='Malé'!N29
A39: Malédiction | B39: Zone de Privation Sensoriel | H39: ='Malé'!J74 | I39: ='Règles'!C182 | K39: =F!$A$5 | L39: =F!$A$18 | S39: ='Malé'!N74
A40: Malédiction | B40: Fuite de Vitalité | H40: ='Malé'!J93 | I40: ='Règles'!C169 | K40: =F!$A$5 | L40: =F!$A$11 | S40: ='Malé'!N93
...

Sheet L
A1: Mot | B1: Type de Mot | C1: Type de Sorts | D1: Difficulté | E1: Drain | F1: Description | G1: Conditions | H1: Domaine
A2: Boost | B2: Liaison | C2: Tous | D2: 0 | E2: X | F2: Lorsque le sort est lancé le personnage peux dépenser autant de mana que souhaité pour augmenter la puissance du sort d'autant, maximum 2 par dés
A3: Long | B3: Liaison | C3: Tous | D3: 2 | E3: 2 | F3: La distance de diffusion du sort est doublée | G3: Diffusion avec distance magique
A4: Large | B4: Liaison | C4: Tous | D4: 0 | E4: 2 | F4: La zone de propagation du sort est doublée | G4: Propagation de type AOE
A5: Aléa | B5: Liaison | C5: Tous | D5: X | E5: X | F5: Le sort est associé à X autres mots de pouvoir, lorsque le sort est lancé seul l'un d'eux est sélectionné, PWR +X | G5: X maximum 3 | H5: 🌀 Chaos
A6: Aléatoire | B6: Liaison | C6: Tous | D6: 0 | E6: 0 | F6: Le sort a 50% de chance de s'appliquer sur chaque cible, PWR +2
A7: Filtre | B7: Liaison | C7: Tous | D7: 4 | E7: 0 | F7: Le sort n'affecte pas les alliés du lanceur de sort (ni le lanceur du sort lui même)
A8: Concentration | B8: Liaison | C8: Tous | D8: 2 | E8: 2 | F8: Chaque cases du sort rattaché à sa zone d'effet qui est bloquée par la typologie du lieu où il est lancé augmente la puissance du sort de 1, maximum 2 x dés
A9: Ephémère | B9: Liaison | C9: Tous | D9: 0 | E9: 0 | F9: Le sort d'invocation ne dure qu'un cycle unique, l'invocation est avantagé a ses tests & jets | H9: ⚡ Foudre
A10: Drain | B10: Liaison | C10: Tous | D10: 0 | E10: 0 | F10: Le sort doit inclure deux mots, en duo ou avec une annexe : l'un pour endommager une ressource, l'autre pour soigner celle ci; les dégats aurons alors lieu sur la cible et le soin sur le lanceur du sort, le montant soigné ne peux être supérieur à la perte réelle de la dite ressource par la cible
A11: Combo | B11: Liaison | C11: Tous | D11: 2 | E11: 0 | F11: Le sort doit inclure deux mots, en duo ou avec une annexe : les deux mots doivent avoir un lien évident et explicite formant une combinaison logique; alors le sort reçoit PWR +1
A12: Perçant | B12: Liaison | C12: Attaque | D12: 2 | E12: 2 | F12: L'attaque issus du sort génère des dégats perçants (ignore la moitié de l'absorption de la cible) | H12: 🔥 Feu, ❄️ Glace, ⚡ Foudre
A13: Biorythme | B13: Liaison | C13: Récup | D13: 2 | E13: 4 | F13: Le soin produit par le sort génère deux fois moins de fatigue le cas échéant | H13: ❤️ Vie
A14: Intelligent | B14: Liaison | D14: 4 | E14: 2 | F14: Le sort n'affecte que les alliés ou les ennemis, au choix du lanceur de sort | H14: 🔮 Magie
A15: Némésis | B15: Liaison | D15: 2 | E15: 2 | F15: Le sort n'affecte que les ennemis du lanceur de sort | H15: 🩸 Impie
A16: Sacrifice | B16: Liaison | D16: 0 | E16: 0 | F16: Le lanceur de sort perd autant de PV que le drain minimum du sort, PWR +2 | H16: 🩸 Impie
A17: Nuance | B17: Liaison | D17: 2 | E17: 2 | F17: Si le sort produit ses effets contre ou en rapport avec un domaine ou un élément, cet effet considère l'ensemble des domaines du même cercle (à savoir : Energie, Matière, Prime, Origine, Eternel, Cycle, Nature, Mental, Magie)
A18: Alignement | B18: Liaison | D18: 2 | E18: 2 | F18: Si le sort produit ses effets contre ou en rapport avec un domaine Divin ou Occulte il affecte tous les domaines de ce type (Divin : Sacré, Vie, Lumière, Loi; Occulte : Impie, Mort, Ombre, Chaos)
A19: Présence | B19: Liaison | D19: 4 | E19: 4 | F19: Le sort qui fait apparaitre des entitées magiques deviens un enchantement qui maintient la présence de ces dernières, provoquant un déplacement de ces derniers (selon les règles appropriées du sort) à chaque tour au même rang d'initiative que le moment où le sort a été lancé | H19: 🔮 Magie
A20: Interruption | B20: Liaison | D20: 2 | E20: 2 | F20: Le sort peux être lancé en interruption, mais requière malgré tout les actions simples habituels (et non une ACTR comme les sorts dont le mot de pouvoir est une interruption)
A25: Impersonalisation | B25: Liaison | C25: Tous | D25: 4 | E25: 2 | F25: Le sort remplace les références au "lancer de sort" avec une cible (au contact ou à distance le cas échéant) | H25: Tous
A28: ??? | B28: Liaison | C28: Tous | D28: 2 | E28: 2 | F28: Si la cible du sort est recouvert par l'élément (de façon intense) associé au domaine de la [clé], le sort est assuré (mini 4) et majoré (+1 par dés) | H28: 🔥 Feu (vs FOR), ❄️ Glace (vs DEX), ⚡ Foudre (vs AGI), 🪨 Terre (vs FOR),💧 Eau (vs DEX), 🌪️ Air (vs AGI), ☀️ Lumière (vs PER), 🌑 Ombre (vs PER), 🌿 Flore (vs PER)
A29: ??? | B29: Liaison | C29: Tous | D29: 0 | E29: 0 | F29: Condition supplémentaire : La cible du sort est recouvert par l'élément (de façon intense) associé au domaine de la [clé], le sort est assuré (mini 4) et majoré (+1 par dés) | H29: 🔥 Feu (vs FOR), ❄️ Glace (vs DEX), ⚡ Foudre (vs AGI), 🪨 Terre (vs FOR),💧 Eau (vs DEX), 🌪️ Air (vs AGI), ☀️ Lumière (vs PER), 🌑 Ombre (vs PER), 🌿 Flore (vs PER)
A30: Extinction | B30: Liaison | C30: Négatif | D30: 0 | E30: 0 | F30: L'effet d'alignement négatif produit par le sort voit son jet multipliés par 0.5 x le niveau de gravité de la blessure la plus élevé de la cible | H30: ☠️ Mort
A31: ??? | B31: Liaison | C31: Négatif | D31: 2 | E31: 2 | F31: L'effet d'alignement négatif produit par le sort voit son jet augmenté de 1D6 supplémentaire par niveau de gravité de la blessure la plus élevé de la cible, maximum 1D6 par niveau du sort | H31: ☠️ Mort
A32: ??? | B32: Liaison | C32: Positif | D32: 0 | E32: 0 | F32: L'effet d'alignement positif produit par le sort voit son jet multipliés par 0.5 x le niveau de gravité de la blessure la plus élevé de la cible | H32: ❤️ Vie
A33: ??? | B33: Liaison | C33: Positif | D33: 2 | E33: 2 | F33: L'effet d'alignement positif produit par le sort voit son jet augmenté de 1D6 supplémentaire par niveau de gravité de la blessure la plus élevé de la cible, maximum 1D6 par niveau du sort | H33: ❤️ Vie
A34: ??? | B34: Liaison | C34: Aligné | D34: 0 | E34: 0 | F34: L'effet d'alignement positif ou négatif produit par le sort voit son jet multipliés par 0.5 x le niveau du trauma de la blessure la plus élevé de la cible | H34: 🧩 Mental
A35: ??? | B35: Liaison | C35: Aligné | D35: 2 | E35: 2 | F35: L'effet d'alignement positif ou négatif produit par le sort voit son jet augmenté de 1D6 supplémentaire par niveau de gravité du trauma la plus élevé de la cible, maximum 1D6 par niveau du sort | H35: 🧩 Mental
A36: ??? | B36: Liaison | C36: Tous | D36: 2 | E36: 0 | F36: L'effet produit par le sort voit son jet augmenté de 2 supplémentaire par adversaire autour de la cible, maximum 2 par niveau du sort | H36: 🛡️ Guerre
A37: ??? | B37: Liaison | C37: Tous | D37: 2 | E37: 0 | F37: L'effet produit par le sort voit son jet majoré 1x / 2x ou 3x mais surviens avec un décalage de 1 / 2 / 3 cycle complets, si le lanceur de sort est déconcentré entre temps l'effet est dissipé sans se produire | H37: 💢 Vide
A38: ??? | B38: Liaison | C38: Attaque | D38: 2 | E38: 2 | F38: Les dégats infligés via le sort provoque un soin de l'endurance du lanceur de sort à hauteur de la moitié des ressources (non temporaires) perdues | H38: ☠️ Mort
... A58: ??? | B58: Liaison | C58: Aligné | D58: 2 | E58: 2 | F58: L'effet d'alignement positif ou négatif produit par le sort voit son jet augmenté de 1D6 supplémentaire par niveau de gravité du trauma la plus élevé du lanceur de sort, maximum 1D6 par niveau du sort | H58: 🧩 Mental
A59: Augmentation | B59: Liaison | C59: Attaque | D59: 2 | E59: 2 | F59: L'attaque issus du sort ne fonctionne/n'affecte que le type de cible contre lequel la [clé] choisit est fort, les dégats sont majorés (+1 par dés) et assuré (minimum des dés 3) | H59: ='Règles'!D139
A60: ??? | B60: Liaison | C60: Attaque | D60: 2 | E60: 2 | F60: Les dégats du sort sont localisés (choix de la localisation lors du lancement du sort) | H60: 👁️ Vision
A61: ??? | B61: Liaison | C61: Attaque | D61: -2 | E61: 0 | F61: Les dégats du sort multiplié par 0.5 du rang de la lésion la plus élevée (en deça du rang 3 les dégats sont identiques ou réduits) | H61: ☠️ Mort
A62: ??? | B62: Liaison | C62: Attaque | D62: -2 | E62: 0 | F62: Les dégats du sort n'inflige pas de lésions | H62: ☀️ Lumière, 🌑 Ombre
A63: ??? | B63: Liaison | C63: Attaque | D63: -4 | E63: 0 | F63: Les dégats du sort sont limités par l'endurance actuelle (4 si max) | H63: TODO, 💢 Vide
A64: ??? | B64: Liaison | C64: Attaque | D64: -4 | E64: 0 | F64: Les dégats du sort sont limités par la vitalité actuelle (4 si max) | H64: TODO, 💢 Vide
A65: ??? | B65: Liaison | C65: Attaque | D65: -4 | E65: 0 | F65: Les dégats du sort sont concussant, ils n'inflige donc pas de dégats permanents | H65: ⚖️ Loi, 🌀 Chaos
...

Sheet A
A1: Mot | B1: Type de Mot | C1: Type de Sorts | D1: Difficulté | E1: Drain | F1: Description | G1: Conditions | H1: Domaine
A2: Annexe | B2: Avancé | D2: X | E2: X | F2: Le sort est avancé (voir les règles), entre autre il requière une ACTS de plus pour être lancé, de plus le sort est associé à un second mot de pouvoir, cet effet subit PWR-2, le malus de PWR ne peux pas être supérieur à 4 une fois tous les mots associés | G2: Le malus de PWR ne peux pas être supérieur à 4 une fois tous les mots associés
A3: Duo | B3: Avancé | D3: X | E3: X | F3: Le sort est avancé (voir les règles), entre autre il requière une ACTS de plus pour être lancé, de plus le sort est associé à un second mot de pouvoir, les deux effets subissent PWR-1, le malus de PWR ne peux pas être supérieur à 4 une fois tous les mots associés | G3: Le malus de PWR ne peux pas être supérieur à 4 une fois tous les mots associés
A4: Supérieur | B4: Avancé | D4: X | E4: X | F4: Le sort est avancé (voir les règles), entre autre il requière une ACTS de plus pour être lancé, de plus le sort est reçoit PWR +1
B5: Avancé
B6: Avancé
B7: Avancé
B8: Avancé
B9: Avancé
B10: Avancé
B11: Avancé
B12: Avancé
B13: Avancé

Sheet F
A1: Mot | B1: Type de Mot | C1: Type de Forme | D1: Limitations | E1: Difficulté | F1: Drain | G1: Description | H1: Particularités | I1: Domaine
A2: Soi | B2: Forme | C2: Diffusion | D2: Def, Enc, Eff | E2: -2 | F2: -2 | G2: Portée : Sans, Vecteur : Sans, Cible soi possible
A3: Contact | B3: Forme | C3: Diffusion | D3: Off, Def, Enc, Eff, Inv | E3: 0 | F3: 0 | G3: Portée : Mêlée, Vecteur : Touché, Cible soi possible | H3: Défendable, Interceptible
A4: Projectile | B4: Forme | C4: Diffusion | D4: Off | E4: 4 | F4: 2 | G4: Portée : Portée magique x2, Vecteur : Vue | H4: Défendable, Interceptible
A5: Manifestation | B5: Forme | C5: Diffusion | D5: Off, Def, Enc, Eff, Inv | E5: 2 | F5: 2 | G5: Portée : Portée magique x1, Vecteur : Vue, Cible soi possible
A6: Mot | B6: Forme | C6: Diffusion | D6: Off, Def, Enc, Eff | E6: 6 | F6: 4 | G6: Portée : Portée magique x3, Vecteur : Voix | I6: Loi, Sacre
A7: Regard | B7: Forme | C7: Diffusion | D7: Off, Def, Enc, Eff | E7: 6 | F7: 4 | G7: Portée : Portée magique x3, Vecteur : Vue | I7: Chaos, Impie
A8: Reflet | B8: Forme | C8: Diffusion | D8: Off, Def, Eff | E8: 4 | F8: 2 | G8: Portée : Lieu, Vecteur : Reflets | I8: Illusion
A9: Nom | B9: Forme | C9: Diffusion | D9: Off, Def, Enc, Eff | E9: 4 | F9: 2 | G9: Portée : Lieu, Vecteur : Voix | I9: Impie
A10: * | B10: * | C10: * | D10: * | E10: * | F10: * | G10: *
A11: Unique | B11: Forme | C11: Propagation | E11: 0 | F11: 0 | G11: Touche une cible unique
A12: Carré | B12: Forme | C12: Propagation | E12: 2 | F12: 2 | G12: Touche une cible et 1 case à proximité (AOE 3)
A13: Cercle | B13: Forme | C13: Propagation | E13: 0 | F13: 2 | G13: Comme carré mais ignore la cible (n'affecte que les cases à proximité donc, utile pour les novas)
A14: Croix | B14: Forme | C14: Propagation | E14: 2 | F14: 2 | G14: Touche une cible et jusqu'à 2 cases de chaque coté en croix (AOE spéciale)
A15: Rayon | B15: Forme | C15: Propagation | E15: 2 | F15: 2 | G15: Touche une cible et jusqu'à 4 cases derrière celle ci (AOE spéciale)
A16: Ligne | B16: Forme | C16: Propagation | E16: 2 | F16: 2 | G16: Touche une cible et jusqu'à 3 cases sur chaque cotés (face au lanceur de sort) (AOE spéciale)
A17: Cône | B17: Forme | C17: Propagation | E17: 2 | F17: 2 | G17: Touche une cible, 3 cases de largeur et 2 cases de profondeur derrières elles (AOE spéciale)
A18: Zone | B18: Forme | C18: Propagation | E18: 4 | F18: 4 | G18: Touche une cible et 3 cases à proximité (AOE 7)
A19: Ciel | B19: Forme | C19: Propagation | E19: 4 | F19: 4 | G19: Touche une cible et 5 cases à proximité (AOE 9), dans les airs uniquement
A20: Surface | B20: Forme | C20: Propagation | E20: 4 | F20: 4 | G20: Touche une cible et 5 cases à proximité (AOE 9) sur une surface/hauteur identique à la cible
A21: Ombre | B21: Forme | C21: Propagation | E21: 4 | F21: 4 | G21: Touche une cible et 5 cases à proximité (AOE 9) qui partage la même pénombre
A22: Lumière | B22: Forme | C22: Propagation | E22: 4 | F22: 4 | G22: Touche une cible et 5 cases à proximité (AOE 9) qui partage la même luminosité
A23: * | B23: * | C23: * | D23: * | E23: * | F23: * | G23: *
A24: Puit | B24: Forme | C24: Structure | D24: Off, Def, Eff | E24: 0 | F24: 0 | G24: Le sort s'applique au moment où il est lancé puis aux deux rounds d'après, même cible, la cible doit être un lieu | H24: PWR -2/-2/-2 (6)
A25: Echos | B25: Forme | C25: Structure | D25: Off, Def, Eff | E25: 2 | F25: 2 | G25: Le sort s'applique au moment où il est lancé puis aux deux rounds d'après, même cible, la cible doit être un lieu | H25: PWR -1/-2/-3 (6)
A26: Chaine | B26: Forme | C26: Structure | D26: Off | E26: 2X | F26: 2X | G26: Le sort s'applique puis change de cible, la nouvelle cible doit être valide, jusqu'à X fois en tout | H26: PWR +0/-1/-2/... (9) | I26: Foudre
A27: Souffle | B27: Forme | C27: Structure | D27: Off, Eff | E27: 4 | F27: 4 | G27: Le sort s'applique normalement mais une version diminuée du sort affecte également les cibles adjacentes (en AOE la portée de ce souffle est équivalant à la distance d'AOE) | H27: PWR +0/-2 | I27: Feu
A28: Lent | B28: Forme | C28: Structure | D28: Off, Enc, Eff | E28: 2X | F28: 2X | G28: Le sort s'applique après un délai de X rounds, maximum 3 | H28: PWR +X | I28: Glace
A29: Poison | B29: Forme | C29: Structure | D29: Off, Eff | E29: 2 | F29: 2 | G29: Le sort s'applique au moment où il est lancé puis aux deux rounds d'après, même cible (lieu ou cible) | H29: PWR -3/-2/-1 | I29: Poison
A30: Double | B30: Forme | C30: Structure | D30: Off, Eff | E30: 2 | F30: 0 | G30: Le sort s'applique sur deux cibles distincts, ces deux cibles sont nécessaires | H30: PWR -1
A31: Multiple | B31: Forme | C31: Structure | D31: Off, Eff | E31: 2X | F31: 2X | G31: Le sort s'applique sur une cible + X autres cibles distincts | H31: PWR -1
A32: Activable | B32: Forme | C32: Structure | D32: Off, Def, Eff, Enc | E32: 0 | F32: 0 | G32: Le sort ne s'applique pas au moment où il est lancé, la cible/zone devient un enchantement qui déclanche les effets si une cible viable la touche, l'enchantement est défaussé après activation, le sort ne peux pas être lancé directement sur une cible correspondant | H32: PWR +2
A33: Statique | B33: Forme | C33: Structure | D33: Off, Def, Eff | E33: 0 | F33: 0 | G33: Le sort ne s'applique pas au moment où il est lancé, la cible/zone devient un enchantement qui déclanche les effets si une cible viable la touche ou débute son round à son contact, ce qui décharge une fois l'enchantement | H33: PWR -1
A34: Chaos | B34: Forme | C34: Structure | D34: Off, Def, Eff, Enc | E34: 0 | F34: 0 | G34: Le sort s'applique sur X cibles (aléatoires) parmi Y cibles dans la zone d'effet | H34: PWR +Y-X (max 3)
A35: Vague | B35: Forme | C35: Structure | D35: Off, Eff | E35: 0 | F35: 0 | G35: Le sort, nécessairement en AOE, ne touche que les premières cibles d'une même lignes (en provenance de la cible d'origine de l'AOE), celles qui sont derrière ne sont pas affectée | H35: PWR +1 | I35: Eau
A36: Orbe | B36: Forme | C36: Structure | D36: Off, Def, Eff | E36: 2 | F36: 2 | G36: Comme statique mais peux être déplacé via une ACTL du lanceur de sort, AOE maximum 5 | H36: PWR -2
A37: Myriade | B37: Forme | C37: Structure | D37: Off, Eff | E37: 2X | F37: 2X | G37: Le sort s'applique X fois sur la cible | H37: PWR -3
A38: Pluie | B38: Forme | C38: Structure | D38: Off, Def, Eff | E38: 0 | F38: 0 | G38: Le sort s'applique au moment où il est lancé puis aux cinq rounds d'après, même cible, la cible doit être un lieu | H38: PWR -3/-3/-3/-3/-3/-3 (6)
A39: Sol | B39: Forme | C39: Structure | D39: Off, Def, Eff | E39: 0 | F39: 0 | G39: Le sort ne s'applique pas au moment où il est lancé, la cible/zone devient un enchantement qui déclanche les effets si une cible viable la touche ou débute son round à son contact | H39: PWR -3
A40: Epieu | B40: Forme | C40: Structure | D40: Off | E40: 2 | F40: 2 | G40: Le projectile issus du sort traverse chaque cible qui se trouve sur son passage, chaque nouvelle cible subit des effets réduits (PWR -1) | H40: PWR +0/-1/-2/... (9)
...

Sheet Dest
A1: ✸
A2: Latin | B2: Mot arcanique | C2: Mot vulguaire | D2: Type de Mot | E2: Type de Cible | F2: Difficulté | G2: Drain | H2: Description | I2: Clés | J2: Prod
A3: Ruptura (Rupture) | B3: Kinrupt (Kin + rupt) | C3: Destruction | D3: Pouvoir | E3: Cible | F3: 2 | G3: 2 | H3: Produit un effet d'attaque physique (armure) infligeant [Magnitude] de dégats physique (PV) basés sur l'élément [clé] | I3: 🔥 Feu: Kinruptar (vs FOR), ❄️ Glace: Kinruptis (vs DEX), ⚡ Foudre: Kinruptor (vs AGI), ☠️ Mort: Kinruptus (vs CON), ☢️ Toxique: Kinruptex (vs CON), ⚔️ Acier: Kinruptan (vs FOR, DEX, AGI, PER), 🌿 Flore: Kinruptiln (vs PER) | J3: =CONCAT(CONCAT(C3, " "),$A$1)
A4: Iungo (Joindre) | B4: Keljung (Kel + jung) | C4: Conjuration | D4: Pouvoir | E4: Cible | F4: 2 | G4: 2 | H4: Produit un effet d'attaque physique (armure) infligeant [Magnitude x0.66] de dégats physique (PV) basés sur l'élément des arcanes | I4: ✡️ Arcane: Keljungys (vs MAG) | J4: =CONCAT(CONCAT(C4, " "),$A$1)
A5: Occulto (Cacher) | B5: Krucclt (Kru + cclt) | C5: Mystification | D5: Pouvoir | E5: Cible | F5: 2 | G5: 2 | H5: Produit un effet d'attaque physique (armure) infligeant [Magnitude] de dégats mentaux (PS) basés sur l'élément [clé] | I5: 🎭 Illusion: Kruccltin (vs VOL) | J5: =CONCAT(CONCAT(C5, " "),$A$1)
A6: Nihil (Rien) | B6: Kranihil (Kra + nihil) | C6: Annihilation | D6: Pouvoir | E6: Cible | F6: 2 | G6: 2 | H6: Produit un effet d'attaque mentale (résolution) infligeant [Magnitude] de dégats physique (PV) basés sur l'élément [clé] | I6: ⚖️ Loi: Kranihilem (vs VOL), 🌀 Chaos: Kranihilix (vs VOL), ✨ Sacre: Kranihiliel (vs SAG), 🩸 Impie: Kranihilun (vs RUS) | J6: =CONCAT(CONCAT(C6, " "),$A$1)
A7: Profano (Souiller) | B7: Kaprofan (Ka + profan) | C7: Profanation | D7: Pouvoir | E7: Cible | F7: 2 | G7: 2 | H7: Produit un effet d'attaque mentale (résolution) infligeant [Magnitude] de dégats mentaux (PS) basés sur l'élément [clé] | I7: 🧩 Mental: Kaprofanend (vs VOL) | J7: =CONCAT(CONCAT(C7, " "),$A$1)
A8: Gressus (Pas, marche) | B8: Kintrans (Kin + trans) | C8: Transgression | D8: Pouvoir | E8: Cible | F8: 2 | G8: 2 | H8: Produit un effet d'attaque mentale (résolution) infligeant [Magnitude] de dégats karmique (PK) basés sur l'élément [clé] | I8: ⚖️ Loi: Kintransem (vs VOL) | J8: =CONCAT(CONCAT(C8, " "),$A$1)
A9: Luo (Payer, laver) | B9: Krulex (Kru + lex) | C9: Expiation | D9: Pouvoir | E9: Cible | F9: 2 | G9: 2 | H9: Produit un effet d'attaque mentale (résolution) infligeant [Magnitude] de dégats pranique (PC) basés sur l'élément [clé] | I9: ☢️ Toxique: Krulexex (vs VOL) | J9: =CONCAT(CONCAT(C9, " "),$A$1)
A10: Torsio (Torsion) | B10: Keltor (Kel + tor) | C10: Distorsion | D10: Pouvoir | E10: Cible | F10: 2 | G10: 2 | H10: Produit un effet d'attaque mentale (résolution) infligeant [Magnitude] de dégats arcanique (PM) basés sur l'élément [clé] | I10: ✡️ Arcane: Keltorys (vs MAG) | J10: =CONCAT(CONCAT(C10, " "),$A$1)
